Opened web browser at the application URL.
localhost:6868 ---
 Main Application Server on http://127.0.0.1:5000 ---
Received request on /api/connect
Resetting entire application connection state...
Application state has been fully reset.
Connecting without SSL for ws:// connection (mock server).
Failed to connect to Cortex WebSocket at ws://localhost:6868: [Errno 10061] WSAECONNREFUSED
Error on /api/connect: Could not connect to EMOTIV Launcher. Is it running?
Traceback (most recent call last):
  File "C:\Users\USUARIO\Documents\MVP for mental health quality\backend\cortex_client.py", line 98, in connect_and_authorize
    self.ws = websocket.create_connection(self.url, sslopt=ssl_options)
              ^^^^^^^^^^^^^^^^^^^^^^^^^^^^^^^^^^^^^^^^^^^^^^^^^^^^^^^^^
  File "C:\Users\USUARIO\miniconda3\envs\mvp_mental_health\Lib\site-packages\websocket\_core.py", line 646, in create_connection
    websock.connect(url, **options)
  File "C:\Users\USUARIO\miniconda3\envs\mvp_mental_health\Lib\site-packages\websocket\_core.py", line 256, in connect
    self.sock, addrs = connect(
                       ^^^^^^^^
  File "C:\Users\USUARIO\miniconda3\envs\mvp_mental_health\Lib\site-packages\websocket\_http.py", line 145, in connect
    sock = _open_socket(addrinfo_list, options.sockopt, options.timeout)
           ^^^^^^^^^^^^^^^^^^^^^^^^^^^^^^^^^^^^^^^^^^^^^^^^^^^^^^^^^^^^^
  File "C:\Users\USUARIO\miniconda3\envs\mvp_mental_health\Lib\site-packages\websocket\_http.py", line 232, in _open_socket
    raise err
  File "C:\Users\USUARIO\miniconda3\envs\mvp_mental_health\Lib\site-packages\websocket\_http.py", line 209, in _open_socket
    sock.connect(address)
  File "C:\Users\USUARIO\miniconda3\envs\mvp_mental_health\Lib\site-packages\eventlet\greenio\base.py", line 251, in connect
    socket_checkerr(fd)
  File "C:\Users\USUARIO\miniconda3\envs\mvp_mental_health\Lib\site-packages\eventlet\greenio\base.py", line 50, in socket_checkerr
    raise OSError(err, errno.errorcode[err])
ConnectionRefusedError: [Errno 10061] WSAECONNREFUSED

The above exception was the direct cause of the following exception:

Traceback (most recent call last):
  File "C:\Users\USUARIO\Documents\MVP for mental health quality\backend\scoring_server.py", line 158, in connect_and_query_headsets
    headsets = client.connect_and_authorize()
               ^^^^^^^^^^^^^^^^^^^^^^^^^^^^^^
  File "C:\Users\USUARIO\Documents\MVP for mental health quality\backend\cortex_client.py", line 104, in connect_and_authorize
    raise ConnectionRefusedError("Could not connect to EMOTIV Launcher. Is it running?") from e
ConnectionRefusedError: Could not connect to EMOTIV Launcher. Is it running?
